2022-09-05 22:49:51: <app.py, 1457> Exception on /diskinfo/disk1s1s1 [GET]
Traceback (most recent call last):
  File "/usr/local/lib/python3.9/site-packages/flask/app.py", line 2073, in wsgi_app
    response = self.full_dispatch_request()
  File "/usr/local/lib/python3.9/site-packages/flask/app.py", line 1518, in full_dispatch_request
    rv = self.handle_user_exception(e)
  File "/usr/local/lib/python3.9/site-packages/flask/app.py", line 1516, in full_dispatch_request
    rv = self.dispatch_request()
  File "/usr/local/lib/python3.9/site-packages/flask/app.py", line 1502, in dispatch_request
    return self.ensure_sync(self.view_functions[rule.endpoint])(**req.view_args)
  File "/Users/wanghaoyang/Desktop/project/code/python/monitor/flask_monitor/bworker_views.py", line 70, in get_diskinfo
    if ":" not in image_name:
TypeError: a bytes-like object is required, not 'str'
2022-09-05 22:53:28: <app.py, 1457> Exception on /diskinfo/disk1s1s1 [GET]
Traceback (most recent call last):
  File "/usr/local/lib/python3.9/site-packages/flask/app.py", line 2073, in wsgi_app
    response = self.full_dispatch_request()
  File "/usr/local/lib/python3.9/site-packages/flask/app.py", line 1518, in full_dispatch_request
    rv = self.handle_user_exception(e)
  File "/usr/local/lib/python3.9/site-packages/flask/app.py", line 1516, in full_dispatch_request
    rv = self.dispatch_request()
  File "/usr/local/lib/python3.9/site-packages/flask/app.py", line 1502, in dispatch_request
    return self.ensure_sync(self.view_functions[rule.endpoint])(**req.view_args)
  File "/Users/wanghaoyang/Desktop/project/code/python/monitor/flask_monitor/bworker_views.py", line 63, in get_diskinfo
    return jsonify(images), status.HTTP_200_OK
  File "/usr/local/lib/python3.9/site-packages/flask/json/__init__.py", line 361, in jsonify
    f"{dumps(data, indent=indent, separators=separators)}\n",
  File "/usr/local/lib/python3.9/site-packages/flask/json/__init__.py", line 139, in dumps
    rv = _json.dumps(obj, **kwargs)
  File "/usr/local/Cellar/python@3.9/3.9.5/Frameworks/Python.framework/Versions/3.9/lib/python3.9/json/__init__.py", line 234, in dumps
    return cls(
  File "/usr/local/Cellar/python@3.9/3.9.5/Frameworks/Python.framework/Versions/3.9/lib/python3.9/json/encoder.py", line 199, in encode
    chunks = self.iterencode(o, _one_shot=True)
  File "/usr/local/Cellar/python@3.9/3.9.5/Frameworks/Python.framework/Versions/3.9/lib/python3.9/json/encoder.py", line 257, in iterencode
    return _iterencode(o, 0)
  File "/usr/local/lib/python3.9/site-packages/flask/json/__init__.py", line 57, in default
    return super().default(o)
  File "/usr/local/Cellar/python@3.9/3.9.5/Frameworks/Python.framework/Versions/3.9/lib/python3.9/json/encoder.py", line 179, in default
    raise TypeError(f'Object of type {o.__class__.__name__} '
TypeError: Object of type bytes is not JSON serializable
2022-09-05 22:53:29: <app.py, 1457> Exception on /diskinfo/disk1s1s1 [GET]
Traceback (most recent call last):
  File "/usr/local/lib/python3.9/site-packages/flask/app.py", line 2073, in wsgi_app
    response = self.full_dispatch_request()
  File "/usr/local/lib/python3.9/site-packages/flask/app.py", line 1518, in full_dispatch_request
    rv = self.handle_user_exception(e)
  File "/usr/local/lib/python3.9/site-packages/flask/app.py", line 1516, in full_dispatch_request
    rv = self.dispatch_request()
  File "/usr/local/lib/python3.9/site-packages/flask/app.py", line 1502, in dispatch_request
    return self.ensure_sync(self.view_functions[rule.endpoint])(**req.view_args)
  File "/Users/wanghaoyang/Desktop/project/code/python/monitor/flask_monitor/bworker_views.py", line 63, in get_diskinfo
    return jsonify(images), status.HTTP_200_OK
  File "/usr/local/lib/python3.9/site-packages/flask/json/__init__.py", line 361, in jsonify
    f"{dumps(data, indent=indent, separators=separators)}\n",
  File "/usr/local/lib/python3.9/site-packages/flask/json/__init__.py", line 139, in dumps
    rv = _json.dumps(obj, **kwargs)
  File "/usr/local/Cellar/python@3.9/3.9.5/Frameworks/Python.framework/Versions/3.9/lib/python3.9/json/__init__.py", line 234, in dumps
    return cls(
  File "/usr/local/Cellar/python@3.9/3.9.5/Frameworks/Python.framework/Versions/3.9/lib/python3.9/json/encoder.py", line 199, in encode
    chunks = self.iterencode(o, _one_shot=True)
  File "/usr/local/Cellar/python@3.9/3.9.5/Frameworks/Python.framework/Versions/3.9/lib/python3.9/json/encoder.py", line 257, in iterencode
    return _iterencode(o, 0)
  File "/usr/local/lib/python3.9/site-packages/flask/json/__init__.py", line 57, in default
    return super().default(o)
  File "/usr/local/Cellar/python@3.9/3.9.5/Frameworks/Python.framework/Versions/3.9/lib/python3.9/json/encoder.py", line 179, in default
    raise TypeError(f'Object of type {o.__class__.__name__} '
TypeError: Object of type bytes is not JSON serializable
2022-09-05 22:53:29: <app.py, 1457> Exception on /diskinfo/disk1s1s1 [GET]
Traceback (most recent call last):
  File "/usr/local/lib/python3.9/site-packages/flask/app.py", line 2073, in wsgi_app
    response = self.full_dispatch_request()
  File "/usr/local/lib/python3.9/site-packages/flask/app.py", line 1518, in full_dispatch_request
    rv = self.handle_user_exception(e)
  File "/usr/local/lib/python3.9/site-packages/flask/app.py", line 1516, in full_dispatch_request
    rv = self.dispatch_request()
  File "/usr/local/lib/python3.9/site-packages/flask/app.py", line 1502, in dispatch_request
    return self.ensure_sync(self.view_functions[rule.endpoint])(**req.view_args)
  File "/Users/wanghaoyang/Desktop/project/code/python/monitor/flask_monitor/bworker_views.py", line 63, in get_diskinfo
    return jsonify(images), status.HTTP_200_OK
  File "/usr/local/lib/python3.9/site-packages/flask/json/__init__.py", line 361, in jsonify
    f"{dumps(data, indent=indent, separators=separators)}\n",
  File "/usr/local/lib/python3.9/site-packages/flask/json/__init__.py", line 139, in dumps
    rv = _json.dumps(obj, **kwargs)
  File "/usr/local/Cellar/python@3.9/3.9.5/Frameworks/Python.framework/Versions/3.9/lib/python3.9/json/__init__.py", line 234, in dumps
    return cls(
  File "/usr/local/Cellar/python@3.9/3.9.5/Frameworks/Python.framework/Versions/3.9/lib/python3.9/json/encoder.py", line 199, in encode
    chunks = self.iterencode(o, _one_shot=True)
  File "/usr/local/Cellar/python@3.9/3.9.5/Frameworks/Python.framework/Versions/3.9/lib/python3.9/json/encoder.py", line 257, in iterencode
    return _iterencode(o, 0)
  File "/usr/local/lib/python3.9/site-packages/flask/json/__init__.py", line 57, in default
    return super().default(o)
  File "/usr/local/Cellar/python@3.9/3.9.5/Frameworks/Python.framework/Versions/3.9/lib/python3.9/json/encoder.py", line 179, in default
    raise TypeError(f'Object of type {o.__class__.__name__} '
TypeError: Object of type bytes is not JSON serializable
2022-09-05 22:56:09: <app.py, 1457> Exception on /diskinfo/disk1s1s1 [GET]
Traceback (most recent call last):
  File "/usr/local/lib/python3.9/site-packages/flask/app.py", line 2073, in wsgi_app
    response = self.full_dispatch_request()
  File "/usr/local/lib/python3.9/site-packages/flask/app.py", line 1519, in full_dispatch_request
    return self.finalize_request(rv)
  File "/usr/local/lib/python3.9/site-packages/flask/app.py", line 1538, in finalize_request
    response = self.make_response(rv)
  File "/usr/local/lib/python3.9/site-packages/flask/app.py", line 1730, in make_response
    raise TypeError(
TypeError: The view function did not return a valid response. The return type must be a string, dict, tuple, Response instance, or WSGI callable, but it was a list.
2022-09-05 22:56:10: <app.py, 1457> Exception on /diskinfo/disk1s1s1 [GET]
Traceback (most recent call last):
  File "/usr/local/lib/python3.9/site-packages/flask/app.py", line 2073, in wsgi_app
    response = self.full_dispatch_request()
  File "/usr/local/lib/python3.9/site-packages/flask/app.py", line 1519, in full_dispatch_request
    return self.finalize_request(rv)
  File "/usr/local/lib/python3.9/site-packages/flask/app.py", line 1538, in finalize_request
    response = self.make_response(rv)
  File "/usr/local/lib/python3.9/site-packages/flask/app.py", line 1730, in make_response
    raise TypeError(
TypeError: The view function did not return a valid response. The return type must be a string, dict, tuple, Response instance, or WSGI callable, but it was a list.
